2025-03-13 09:51:03.605 WARNING (SyncWorker_0) [homeassistant.loader] We found a custom integration n8n_conversation_agent which has not been tested by Home Assistant. This component might cause stability problems, be sure to disable it if you experience issues with Home Assistant
2025-03-13 09:51:07.648 WARNING (MainThread) [homeassistant.helpers.frame] Detected that custom integration 'n8n_conversation_agent' calls async_forward_entry_setup for integration, n8n_conversation_agent with title: N8N Test Agent and entry_id: 01JMPSX9JM9HQPH8YP18XSJCAZ, which is deprecated, await async_forward_entry_setups instead at custom_components/n8n_conversation_agent/__init__.py, line 17: hass.async_create_task(. This will stop working in Home Assistant 2025.6, please report it to the author of the 'n8n_conversation_agent' custom integration
2025-03-13 09:51:07.710 WARNING (MainThread) [homeassistant.helpers.frame] Detected code that calls async_forward_entry_setup for integration n8n_conversation_agent with title: N8N Test Agent and entry_id: 01JMPSX9JM9HQPH8YP18XSJCAZ, during setup without awaiting async_forward_entry_setup, which can cause the setup lock to be released before the setup is done. This will stop working in Home Assistant 2025.1, please report this issue
Stack (most recent call last):
  File "<frozen runpy>", line 198, in _run_module_as_main
  File "<frozen runpy>", line 88, in _run_code
  File "/usr/src/homeassistant/homeassistant/__main__.py", line 227, in <module>
    sys.exit(main())
  File "/usr/src/homeassistant/homeassistant/__main__.py", line 213, in main
    exit_code = runner.run(runtime_conf)
  File "/usr/src/homeassistant/homeassistant/runner.py", line 154, in run
    return loop.run_until_complete(setup_and_run_hass(runtime_config))
  File "/usr/local/lib/python3.13/asyncio/base_events.py", line 712, in run_until_complete
    self.run_forever()
  File "/usr/local/lib/python3.13/asyncio/base_events.py", line 683, in run_forever
    self._run_once()
  File "/usr/local/lib/python3.13/asyncio/base_events.py", line 2040, in _run_once
    handle._run()
  File "/usr/local/lib/python3.13/asyncio/events.py", line 89, in _run
    self._context.run(self._callback, *self._args)
  File "/usr/src/homeassistant/homeassistant/config_entries.py", line 2607, in async_forward_entry_setup
    _report_non_awaited_platform_forwards(entry, "async_forward_entry_setup")
  File "/usr/src/homeassistant/homeassistant/config_entries.py", line 1313, in _report_non_awaited_platform_forwards
    report_usage(
  File "/usr/src/homeassistant/homeassistant/helpers/frame.py", line 234, in report_usage
    _LOGGER.warning(msg, stack_info=True)
2025-03-13 09:51:07.711 WARNING (MainThread) [homeassistant.helpers.frame] Detected code that calls async_forward_entry_setup for integration n8n_conversation_agent with title: N8N Agent and entry_id: 01JMQ0ZEPBSD9GNZNC109WTFEY, during setup without awaiting async_forward_entry_setup, which can cause the setup lock to be released before the setup is done. This will stop working in Home Assistant 2025.1, please report this issue
Stack (most recent call last):
  File "<frozen runpy>", line 198, in _run_module_as_main
  File "<frozen runpy>", line 88, in _run_code
  File "/usr/src/homeassistant/homeassistant/__main__.py", line 227, in <module>
    sys.exit(main())
  File "/usr/src/homeassistant/homeassistant/__main__.py", line 213, in main
    exit_code = runner.run(runtime_conf)
  File "/usr/src/homeassistant/homeassistant/runner.py", line 154, in run
    return loop.run_until_complete(setup_and_run_hass(runtime_config))
  File "/usr/local/lib/python3.13/asyncio/base_events.py", line 712, in run_until_complete
    self.run_forever()
  File "/usr/local/lib/python3.13/asyncio/base_events.py", line 683, in run_forever
    self._run_once()
  File "/usr/local/lib/python3.13/asyncio/base_events.py", line 2040, in _run_once
    handle._run()
  File "/usr/local/lib/python3.13/asyncio/events.py", line 89, in _run
    self._context.run(self._callback, *self._args)
  File "/usr/src/homeassistant/homeassistant/config_entries.py", line 2607, in async_forward_entry_setup
    _report_non_awaited_platform_forwards(entry, "async_forward_entry_setup")
  File "/usr/src/homeassistant/homeassistant/config_entries.py", line 1313, in _report_non_awaited_platform_forwards
    report_usage(
  File "/usr/src/homeassistant/homeassistant/helpers/frame.py", line 234, in report_usage
    _LOGGER.warning(msg, stack_info=True)
