2025-02-21 05:15:55.779 WARNING (SyncWorker_0) [homeassistant.loader] We found a custom integration n8n_conversation_agent which has not been tested by Home Assistant. This component might cause stability problems, be sure to disable it if you experience issues with Home Assistant
2025-02-21 05:15:55.779 WARNING (SyncWorker_0) [homeassistant.loader] We found a custom integration wyoming which has not been tested by Home Assistant. This component might cause stability problems, be sure to disable it if you experience issues with Home Assistant
2025-02-21 05:15:57.693 WARNING (MainThread) [homeassistant.helpers.frame] Detected that custom integration 'n8n_conversation_agent' calls async_forward_entry_setup for integration, n8n_conversation_agent with title: N8N Test and entry_id: 01JMJ3D1THQB7N37TPJ8R6N7M8, which is deprecated, await async_forward_entry_setups instead at custom_components/n8n_conversation_agent/__init__.py, line 17: hass.async_create_task(. This will stop working in Home Assistant 2025.6, please report it to the author of the 'n8n_conversation_agent' custom integration
2025-02-21 05:15:57.772 WARNING (MainThread) [homeassistant.helpers.frame] Detected code that calls async_forward_entry_setup for integration n8n_conversation_agent with title: N8N Test and entry_id: 01JMJ3D1THQB7N37TPJ8R6N7M8, during setup without awaiting async_forward_entry_setup, which can cause the setup lock to be released before the setup is done. This will stop working in Home Assistant 2025.1, please report this issue
Stack (most recent call last):
  File "<frozen runpy>", line 198, in _run_module_as_main
  File "<frozen runpy>", line 88, in _run_code
  File "/usr/src/homeassistant/homeassistant/__main__.py", line 227, in <module>
    sys.exit(main())
  File "/usr/src/homeassistant/homeassistant/__main__.py", line 213, in main
    exit_code = runner.run(runtime_conf)
  File "/usr/src/homeassistant/homeassistant/runner.py", line 154, in run
    return loop.run_until_complete(setup_and_run_hass(runtime_config))
  File "/usr/local/lib/python3.13/asyncio/base_events.py", line 707, in run_until_complete
    self.run_forever()
  File "/usr/local/lib/python3.13/asyncio/base_events.py", line 678, in run_forever
    self._run_once()
  File "/usr/local/lib/python3.13/asyncio/base_events.py", line 2033, in _run_once
    handle._run()
  File "/usr/local/lib/python3.13/asyncio/events.py", line 89, in _run
    self._context.run(self._callback, *self._args)
  File "/usr/src/homeassistant/homeassistant/config_entries.py", line 2347, in async_forward_entry_setup
    _report_non_awaited_platform_forwards(entry, "async_forward_entry_setup")
  File "/usr/src/homeassistant/homeassistant/config_entries.py", line 1193, in _report_non_awaited_platform_forwards
    report_usage(
  File "/usr/src/homeassistant/homeassistant/helpers/frame.py", line 234, in report_usage
    _LOGGER.warning(msg, stack_info=True)
2025-02-21 05:15:57.773 WARNING (MainThread) [homeassistant.helpers.frame] Detected code that calls async_forward_entry_setup for integration n8n_conversation_agent with title: N8N and entry_id: 01JMJ3DE2H00TVBT5K8RB4269V, during setup without awaiting async_forward_entry_setup, which can cause the setup lock to be released before the setup is done. This will stop working in Home Assistant 2025.1, please report this issue
Stack (most recent call last):
  File "<frozen runpy>", line 198, in _run_module_as_main
  File "<frozen runpy>", line 88, in _run_code
  File "/usr/src/homeassistant/homeassistant/__main__.py", line 227, in <module>
    sys.exit(main())
  File "/usr/src/homeassistant/homeassistant/__main__.py", line 213, in main
    exit_code = runner.run(runtime_conf)
  File "/usr/src/homeassistant/homeassistant/runner.py", line 154, in run
    return loop.run_until_complete(setup_and_run_hass(runtime_config))
  File "/usr/local/lib/python3.13/asyncio/base_events.py", line 707, in run_until_complete
    self.run_forever()
  File "/usr/local/lib/python3.13/asyncio/base_events.py", line 678, in run_forever
    self._run_once()
  File "/usr/local/lib/python3.13/asyncio/base_events.py", line 2033, in _run_once
    handle._run()
  File "/usr/local/lib/python3.13/asyncio/events.py", line 89, in _run
    self._context.run(self._callback, *self._args)
  File "/usr/src/homeassistant/homeassistant/config_entries.py", line 2347, in async_forward_entry_setup
    _report_non_awaited_platform_forwards(entry, "async_forward_entry_setup")
  File "/usr/src/homeassistant/homeassistant/config_entries.py", line 1193, in _report_non_awaited_platform_forwards
    report_usage(
  File "/usr/src/homeassistant/homeassistant/helpers/frame.py", line 234, in report_usage
    _LOGGER.warning(msg, stack_info=True)
2025-02-21 05:15:57.794 WARNING (MainThread) [homeassistant.util.loop] Detected blocking call to import_module with args ('custom_components.wyoming.assist_satellite',) inside the event loop by custom integration 'wyoming' at custom_components/wyoming/__init__.py, line 68: await hass.config_entries.async_forward_entry_setups(entry, SATELLITE_PLATFORMS) (offender: /usr/src/homeassistant/homeassistant/loader.py, line 1304: return importlib.import_module(f"{self.pkg_path}.{platform_name}")), please report it to the author of the 'wyoming' custom integration
For developers, please see https://developers.home-assistant.io/docs/asyncio_blocking_operations/#import_module
Traceback (most recent call last):
  File "<frozen runpy>", line 198, in _run_module_as_main
  File "<frozen runpy>", line 88, in _run_code
  File "/usr/src/homeassistant/homeassistant/__main__.py", line 227, in <module>
    sys.exit(main())
  File "/usr/src/homeassistant/homeassistant/__main__.py", line 213, in main
    exit_code = runner.run(runtime_conf)
  File "/usr/src/homeassistant/homeassistant/runner.py", line 154, in run
    return loop.run_until_complete(setup_and_run_hass(runtime_config))
  File "/usr/local/lib/python3.13/asyncio/base_events.py", line 707, in run_until_complete
    self.run_forever()
  File "/usr/local/lib/python3.13/asyncio/base_events.py", line 678, in run_forever
    self._run_once()
  File "/usr/local/lib/python3.13/asyncio/base_events.py", line 2033, in _run_once
    handle._run()
  File "/usr/local/lib/python3.13/asyncio/events.py", line 89, in _run
    self._context.run(self._callback, *self._args)
  File "/usr/src/homeassistant/homeassistant/config_entries.py", line 782, in async_setup_locked
    await self.async_setup(hass, integration=integration)
  File "/usr/src/homeassistant/homeassistant/config_entries.py", line 548, in async_setup
    await self.__async_setup_with_context(hass, integration)
  File "/usr/src/homeassistant/homeassistant/config_entries.py", line 637, in __async_setup_with_context
    result = await component.async_setup_entry(hass, self)
  File "/config/custom_components/wyoming/__init__.py", line 68, in async_setup_entry
    await hass.config_entries.async_forward_entry_setups(entry, SATELLITE_PLATFORMS)

2025-02-21 05:15:57.794 ERROR (MainThread) [homeassistant.config_entries] Error setting up entry my satellite for wyoming
Traceback (most recent call last):
  File "/usr/src/homeassistant/homeassistant/config_entries.py", line 637, in __async_setup_with_context
    result = await component.async_setup_entry(hass, self)
             ^^^^^^^^^^^^^^^^^^^^^^^^^^^^^^^^^^^^^^^^^^^^^
  File "/config/custom_components/wyoming/__init__.py", line 68, in async_setup_entry
    await hass.config_entries.async_forward_entry_setups(entry, SATELLITE_PLATFORMS)
  File "/usr/src/homeassistant/homeassistant/config_entries.py", line 2272, in async_forward_entry_setups
    await integration.async_get_platforms(platforms)
  File "/usr/src/homeassistant/homeassistant/loader.py", line 1185, in async_get_platforms
    import_future.result()
    ~~~~~~~~~~~~~~~~~~~~^^
  File "/usr/src/homeassistant/homeassistant/loader.py", line 1185, in async_get_platforms
    import_future.result()
    ~~~~~~~~~~~~~~~~~~~~^^
  File "/usr/src/homeassistant/homeassistant/loader.py", line 1185, in async_get_platforms
    import_future.result()
    ~~~~~~~~~~~~~~~~~~~~^^
  [Previous line repeated 2 more times]
  File "/usr/src/homeassistant/homeassistant/loader.py", line 1173, in async_get_platforms
    platforms.update(self._load_platforms(platform_names))
                     ~~~~~~~~~~~~~~~~~~~~^^^^^^^^^^^^^^^^
  File "/usr/src/homeassistant/homeassistant/loader.py", line 1098, in _load_platforms
    platform_name: self._load_platform(platform_name)
                   ~~~~~~~~~~~~~~~~~~~^^^^^^^^^^^^^^^
  File "/usr/src/homeassistant/homeassistant/loader.py", line 1272, in _load_platform
    cache[full_name] = self._import_platform(platform_name)
                       ~~~~~~~~~~~~~~~~~~~~~^^^^^^^^^^^^^^^
  File "/usr/src/homeassistant/homeassistant/loader.py", line 1304, in _import_platform
    return importlib.import_module(f"{self.pkg_path}.{platform_name}")
           ~~~~~~~~~~~~~~~~~~~~~~~^^^^^^^^^^^^^^^^^^^^^^^^^^^^^^^^^^^^
  File "/usr/src/homeassistant/homeassistant/util/loop.py", line 201, in protected_loop_func
    return func(*args, **kwargs)
  File "/usr/local/lib/python3.13/importlib/__init__.py", line 88, in import_module
    return _bootstrap._gcd_import(name[level:], package, level)
           ~~~~~~~~~~~~~~~~~~~~~~^^^^^^^^^^^^^^^^^^^^^^^^^^^^^^
  File "<frozen importlib._bootstrap>", line 1387, in _gcd_import
  File "<frozen importlib._bootstrap>", line 1360, in _find_and_load
  File "<frozen importlib._bootstrap>", line 1331, in _find_and_load_unlocked
  File "<frozen importlib._bootstrap>", line 935, in _load_unlocked
  File "<frozen importlib._bootstrap_external>", line 1026, in exec_module
  File "<frozen importlib._bootstrap>", line 488, in _call_with_frames_removed
  File "/config/custom_components/wyoming/assist_satellite.py", line 38, in <module>
    from homeassistant.helpers.entity_platform import AddConfigEntryEntitiesCallback
ImportError: cannot import name 'AddConfigEntryEntitiesCallback' from 'homeassistant.helpers.entity_platform' (/usr/src/homeassistant/homeassistant/helpers/entity_platform.py)
2025-02-21 05:15:57.797 ERROR (MainThread) [homeassistant.config_entries] Error setting up entry openwakeword for wyoming
Traceback (most recent call last):
  File "/usr/src/homeassistant/homeassistant/config_entries.py", line 637, in __async_setup_with_context
    result = await component.async_setup_entry(hass, self)
             ^^^^^^^^^^^^^^^^^^^^^^^^^^^^^^^^^^^^^^^^^^^^^
  File "/config/custom_components/wyoming/__init__.py", line 46, in async_setup_entry
    await hass.config_entries.async_forward_entry_setups(entry, service.platforms)
  File "/usr/src/homeassistant/homeassistant/config_entries.py", line 2272, in async_forward_entry_setups
    await integration.async_get_platforms(platforms)
  File "/usr/src/homeassistant/homeassistant/loader.py", line 1185, in async_get_platforms
    import_future.result()
    ~~~~~~~~~~~~~~~~~~~~^^
  File "/usr/src/homeassistant/homeassistant/loader.py", line 1173, in async_get_platforms
    platforms.update(self._load_platforms(platform_names))
                     ~~~~~~~~~~~~~~~~~~~~^^^^^^^^^^^^^^^^
  File "/usr/src/homeassistant/homeassistant/loader.py", line 1098, in _load_platforms
    platform_name: self._load_platform(platform_name)
                   ~~~~~~~~~~~~~~~~~~~^^^^^^^^^^^^^^^
  File "/usr/src/homeassistant/homeassistant/loader.py", line 1272, in _load_platform
    cache[full_name] = self._import_platform(platform_name)
                       ~~~~~~~~~~~~~~~~~~~~~^^^^^^^^^^^^^^^
  File "/usr/src/homeassistant/homeassistant/loader.py", line 1304, in _import_platform
    return importlib.import_module(f"{self.pkg_path}.{platform_name}")
           ~~~~~~~~~~~~~~~~~~~~~~~^^^^^^^^^^^^^^^^^^^^^^^^^^^^^^^^^^^^
  File "/usr/src/homeassistant/homeassistant/util/loop.py", line 201, in protected_loop_func
    return func(*args, **kwargs)
  File "/usr/local/lib/python3.13/importlib/__init__.py", line 88, in import_module
    return _bootstrap._gcd_import(name[level:], package, level)
           ~~~~~~~~~~~~~~~~~~~~~~^^^^^^^^^^^^^^^^^^^^^^^^^^^^^^
  File "<frozen importlib._bootstrap>", line 1387, in _gcd_import
  File "<frozen importlib._bootstrap>", line 1360, in _find_and_load
  File "<frozen importlib._bootstrap>", line 1331, in _find_and_load_unlocked
  File "<frozen importlib._bootstrap>", line 935, in _load_unlocked
  File "<frozen importlib._bootstrap_external>", line 1026, in exec_module
  File "<frozen importlib._bootstrap>", line 488, in _call_with_frames_removed
  File "/config/custom_components/wyoming/wake_word.py", line 14, in <module>
    from homeassistant.helpers.entity_platform import AddConfigEntryEntitiesCallback
ImportError: cannot import name 'AddConfigEntryEntitiesCallback' from 'homeassistant.helpers.entity_platform' (/usr/src/homeassistant/homeassistant/helpers/entity_platform.py)
2025-02-21 05:15:57.799 ERROR (MainThread) [homeassistant.config_entries] Error setting up entry faster-whisper for wyoming
Traceback (most recent call last):
  File "/usr/src/homeassistant/homeassistant/config_entries.py", line 637, in __async_setup_with_context
    result = await component.async_setup_entry(hass, self)
             ^^^^^^^^^^^^^^^^^^^^^^^^^^^^^^^^^^^^^^^^^^^^^
  File "/config/custom_components/wyoming/__init__.py", line 46, in async_setup_entry
    await hass.config_entries.async_forward_entry_setups(entry, service.platforms)
  File "/usr/src/homeassistant/homeassistant/config_entries.py", line 2272, in async_forward_entry_setups
    await integration.async_get_platforms(platforms)
  File "/usr/src/homeassistant/homeassistant/loader.py", line 1185, in async_get_platforms
    import_future.result()
    ~~~~~~~~~~~~~~~~~~~~^^
  File "/usr/src/homeassistant/homeassistant/loader.py", line 1173, in async_get_platforms
    platforms.update(self._load_platforms(platform_names))
                     ~~~~~~~~~~~~~~~~~~~~^^^^^^^^^^^^^^^^
  File "/usr/src/homeassistant/homeassistant/loader.py", line 1098, in _load_platforms
    platform_name: self._load_platform(platform_name)
                   ~~~~~~~~~~~~~~~~~~~^^^^^^^^^^^^^^^
  File "/usr/src/homeassistant/homeassistant/loader.py", line 1272, in _load_platform
    cache[full_name] = self._import_platform(platform_name)
                       ~~~~~~~~~~~~~~~~~~~~~^^^^^^^^^^^^^^^
  File "/usr/src/homeassistant/homeassistant/loader.py", line 1304, in _import_platform
    return importlib.import_module(f"{self.pkg_path}.{platform_name}")
           ~~~~~~~~~~~~~~~~~~~~~~~^^^^^^^^^^^^^^^^^^^^^^^^^^^^^^^^^^^^
  File "/usr/src/homeassistant/homeassistant/util/loop.py", line 201, in protected_loop_func
    return func(*args, **kwargs)
  File "/usr/local/lib/python3.13/importlib/__init__.py", line 88, in import_module
    return _bootstrap._gcd_import(name[level:], package, level)
           ~~~~~~~~~~~~~~~~~~~~~~^^^^^^^^^^^^^^^^^^^^^^^^^^^^^^
  File "<frozen importlib._bootstrap>", line 1387, in _gcd_import
  File "<frozen importlib._bootstrap>", line 1360, in _find_and_load
  File "<frozen importlib._bootstrap>", line 1331, in _find_and_load_unlocked
  File "<frozen importlib._bootstrap>", line 935, in _load_unlocked
  File "<frozen importlib._bootstrap_external>", line 1026, in exec_module
  File "<frozen importlib._bootstrap>", line 488, in _call_with_frames_removed
  File "/config/custom_components/wyoming/stt.py", line 13, in <module>
    from homeassistant.helpers.entity_platform import AddConfigEntryEntitiesCallback
ImportError: cannot import name 'AddConfigEntryEntitiesCallback' from 'homeassistant.helpers.entity_platform' (/usr/src/homeassistant/homeassistant/helpers/entity_platform.py)
